<?xml version="1.0" ?>
<robot name="jethexa">
  <mujoco>
    <compiler meshdir="/home/ubuntu/ros2_ws/src/jethexa_description/meshes/simplify"
              balanceinertia="true"
              strippath="false"/>
  </mujoco>
  <material name="black">
    <color rgba="0.0 0.0 0.0 1.0"/>
  </material>
  <material name="blue">
    <color rgba="0.0 0.0 0.8 1.0"/>
  </material>
  <material name="green">
    <color rgba="0.0 0.8 0.0 1.0"/>
  </material>
  <material name="grey">
    <color rgba="0.2 0.2 0.2 1.0"/>
  </material>
  <material name="orange">
    <color rgba="1.0 0.4235294117647059 0.0392156862745098 1.0"/>
  </material>
  <material name="brown">
    <color rgba="0.8705882352941177 0.8117647058823529 0.7647058823529411 1.0"/>
  </material>
  <material name="red">
    <color rgba="0.8 0.0 0.0 1.0"/>
  </material>
  <material name="yellow">
    <color rgba="1.0 1.0 0.0 1.0"/>
  </material>
  <material name="white">
    <color rgba="1.0 1.0 1.0 1.0"/>
  </material>
  <!-- Used for fixing robot -->
  <link name="base"/>
  <gazebo reference="base">
    <static>true</static>
  </gazebo>
  <joint name="base_joint" type="fixed">
    <parent link="base"/>
    <child link="body_link"/>
    <origin rpy="0 0 0" xyz="0 0 0.075"/>
  </joint>
  <link name="body_link">
    <visual name="body_visual">
      <origin rpy="0.0 0.0 0.0" xyz="0.0 0.0 0.0"/>
      <geometry>
        <mesh filename="body.stl" scale="0.001 0.001 0.001"/>
      </geometry>
      <material name="">
        <color rgba="0.7 0.7 0.7 1"/>
      </material>
    </visual>
    <collision name="body_collision">
      <origin rpy="0.0 0.0 0.0" xyz="0.0 0.0 0.0"/>
      <geometry>
        <mesh filename="body.stl" scale="0.001 0.001 0.001"/>
      </geometry>
      <material name="">
        <color rgba="0.7 0.7 0.7 1"/>
      </material>
    </collision>
    <inertial>
      <origin rpy="0.0 0.0 0.0" xyz="0.0 0.0 0.0"/>
      <mass value="1.03179"/>
      <inertia ixx="1.0" ixy="0.0" ixz="0.0" iyy="1.0" iyz="0.0" izz="1.0"/>
    </inertial>
  </link>
  <!-- Head Pan and Tilt properties -->
  <joint name="head_center_joint" type="fixed">
    <parent link="body_link"/>
    <child link="head_center_link"/>
    <origin rpy="0.0 0.0 0.0" xyz="0.065455 0.0 0.0"/>
  </joint>
  <link name="head_center_link">
    <inertial>
      <origin rpy="0.0 0.0 0.0" xyz="0.0 0.0 0.0"/>
      <mass value="0.05000"/>
      <inertia ixx="1.0" ixy="0.0" ixz="0.0" iyy="1.0" iyz="0.0" izz="1.0"/>
    </inertial>
  </link>
  <joint name="head_pan_joint" type="revolute">
    <parent link="head_center_link"/>
    <child link="head_pan_link"/>
    <axis xyz="0.0 0.0 1.0"/>
    <origin rpy="0.0 0.0 0.0" xyz="0.0 0.0 0.068857338"/>
    <limit effort="10000" lower="-3.14" upper="3.14" velocity="100"/>
    <dynamics damping="0.7"/>
  </joint>
  <link name="head_pan_link">
    <visual name="head_pan_visual">
      <origin rpy="0.0 0.0 0.0" xyz="0.0 0.0 0.0"/>
      <geometry>
        <mesh filename="head_pan.stl" scale="0.001 0.001 0.001"/>
      </geometry>
      <material name="">
        <color rgba="0.7 0.7 0.7 1"/>
      </material>
    </visual>
    <collision name="head_pan_collision">
      <origin rpy="0.0 0.0 0.0" xyz="0.0 0.0 0.0"/>
      <geometry>
        <mesh filename="head_pan.stl" scale="0.001 0.001 0.001"/>
      </geometry>
      <material name="">
        <color rgba="0.7 0.7 0.7 1"/>
      </material>
    </collision>
    <inertial>
      <origin rpy="0.0 0.0 0.0" xyz="0.0 0.0 0.0"/>
      <mass value="0.05000"/>
      <inertia ixx="1.0" ixy="0.0" ixz="0.0" iyy="1.0" iyz="0.0" izz="1.0"/>
    </inertial>
  </link>
  <joint name="head_tilt_joint" type="revolute">
    <parent link="head_pan_link"/>
    <child link="head_tilt_link"/>
    <axis xyz="0.0 0.0 1.0"/>
    <origin rpy="1.5707963267948966 0.0 0.0" xyz="0.00922 0.0 0.017199"/>
    <limit effort="10000" lower="-3.14" upper="3.14" velocity="100"/>
    <dynamics damping="0.7"/>
  </joint>
  <link name="head_tilt_link">
    <visual name="head_tilt_visual">
      <origin rpy="0.0 0.0 0.0" xyz="0.0 0.0 0.0"/>
      <geometry>
        <mesh filename="head_tilt.stl" scale="0.001 0.001 0.001"/>
      </geometry>
      <material name="">
        <color rgba="0.7 0.7 0.7 1"/>
      </material>
    </visual>
    <collision name="head_tilt_collision">
      <origin rpy="0.0 0.0 0.0" xyz="0.0 0.0 0.0"/>
      <geometry>
        <mesh filename="head_tilt.stl" scale="0.001 0.001 0.001"/>
      </geometry>
      <material name="">
        <color rgba="0.7 0.7 0.7 1"/>
      </material>
    </collision>
    <inertial>
      <origin rpy="0.0 0.0 0.0" xyz="0.0 0.0 0.0"/>
      <mass value="0.05000"/>
      <inertia ixx="1.0" ixy="0.0" ixz="0.0" iyy="1.0" iyz="0.0" izz="1.0"/>
    </inertial>
  </link>
  <!-- leg position -->
  <joint name="leg_center_joint_RR" type="fixed">
    <origin rpy="0.0 0.0 0.0" xyz="-0.093205 -0.05098 0.0"/>
    <parent link="body_link"/>
    <child link="leg_center_RR"/>
  </joint>
  <link name="leg_center_RR">
    <inertial>
      <origin rpy="0.0 0.0 0.0" xyz="0.0 0.0 0.0"/>
      <mass value="0.05200"/>
      <inertia ixx="1.0" ixy="0.0" ixz="0.0" iyy="1.0" iyz="0.0" izz="1.0"/>
    </inertial>
  </link>
  <!-- coxa -->
  <joint name="coxa_joint_RR" type="revolute">
    <origin rpy="0.0 0.0 -2.356194490192345" xyz="0.0 0.0 0.0"/>
    <parent link="leg_center_RR"/>
    <child link="coxa_RR"/>
    <axis xyz="0.0 0.0 1.0"/>
    <limit effort="6.0" lower="-3.14" upper="3.14" velocity="0.524"/>
    <dynamics damping="0.7"/>
  </joint>
  <link name="coxa_RR">
    <visual name="coxa_RR_visual">
      <origin rpy="0.0 0.0 0.0" xyz="0.0 0.0 0.0"/>
      <geometry>
        <mesh filename="coxa.stl" scale="0.001 0.001 0.001"/>
      </geometry>
      <material name="">
        <color rgba="0.7 0.7 0.7 1"/>
      </material>
    </visual>
    <collision name="coxa_RR_collision">
      <origin rpy="0.0 0.0 0.0" xyz="0.0 0.0 0.0"/>
      <geometry>
        <mesh filename="coxa.stl" scale="0.001 0.001 0.001"/>
      </geometry>
      <material name="">
        <color rgba="0.7 0.7 0.7 1"/>
      </material>
    </collision>
    <inertial>
      <origin rpy="0.0 0.0 0.0" xyz="0.0 0.0 0.0"/>
      <mass value="0.01312"/>
      <inertia ixx="1.0" ixy="0.0" ixz="0.0" iyy="1.0" iyz="0.0" izz="1.0"/>
    </inertial>
  </link>
  <!-- femur -->
  <joint name="femur_joint_RR" type="revolute">
    <origin rpy="1.5707963267948966 0.0 0.0" xyz="0.04505032 0.0 0.0"/>
    <parent link="coxa_RR"/>
    <child link="femur_RR"/>
    <axis xyz="0.0 0.0 1"/>
    <limit effort="6.0" lower="-3.14" upper="3.14" velocity="0.524"/>
    <dynamics damping="0.7"/>
  </joint>
  <link name="femur_RR">
    <visual name="femur_RR_visual">
      <origin rpy="0.0 0.0 0.0" xyz="0.0 0.0 0.0"/>
      <geometry>
        <mesh filename="R_femur.stl" scale="0.001 0.001 0.001"/>
      </geometry>
      <material name="">
        <color rgba="0.7 0.7 0.7 1"/>
      </material>
    </visual>
    <collision name="femur_RR_collision">
      <origin rpy="0.0 0.0 0" xyz="0.0 0.0 0.0"/>
      <geometry>
        <mesh filename="R_femur.stl" scale="0.001 0.001 0.001"/>
      </geometry>
      <material name="">
        <color rgba="0.7 0.7 0.7 1"/>
      </material>
    </collision>
    <inertial>
      <origin rpy="0.0 0.0 1.0" xyz="0.0 0.0 0.0"/>
      <mass value="0.08737"/>
      <inertia ixx="1.0" ixy="0.0" ixz="0.0" iyy="1.0" iyz="0.0" izz="1.0"/>
    </inertial>
  </link>
  <!-- tibia -->
  <joint name="tibia_joint_RR" type="revolute">
    <origin rpy="0.0 0.0 -1.5707963267948966" xyz="0.07703 0.0 0.0"/>
    <parent link="femur_RR"/>
    <child link="tibia_RR"/>
    <axis xyz="0.0 0.0 1"/>
    <limit effort="6.0" lower="-3.14" upper="3.14" velocity="0.524"/>
    <dynamics damping="0.7"/>
  </joint>
  <link name="tibia_RR">
    <visual name="tibia_RR_visual">
      <origin rpy="0.0 0.0 0.0" xyz="0.0 0.0 0.0"/>
      <geometry>
        <mesh filename="R_tibia.stl" scale="0.001 0.001 0.001"/>
      </geometry>
      <material name="">
        <color rgba="0.7 0.7 0.7 1"/>
      </material>
    </visual>
    <collision name="tibia_RR_collision">
      <origin rpy="0.0 0.0 0.0" xyz="0.0 0.0 0.0"/>
      <geometry>
        <mesh filename="R_tibia.stl" scale="0.001 0.001 0.001"/>
      </geometry>
      <material name="">
        <color rgba="0.7 0.7 0.7 1"/>
      </material>
    </collision>
    <inertial>
      <origin rpy="0.0 0.0 0.0" xyz="0.0 0.0 0.0"/>
      <mass value="0.09016"/>
      <inertia ixx="1.0" ixy="0.0" ixz="0.0" iyy="1.0" iyz="0.0" izz="1.0"/>
    </inertial>
  </link>
  <!-- END -->
  <joint name="end_jointRR" type="fixed">
    <origin rpy="0.0 0.0 0.0" xyz="0.12 0.0 0.0"/>
    <parent link="tibia_RR"/>
    <child link="end_RR"/>
    <axis xyz="0.0 0.0 0.0"/>
  </joint>
  <link name="end_RR">
        </link>
  <!-- leg position -->
  <joint name="leg_center_joint_RM" type="fixed">
    <origin rpy="0.0 0.0 0.0" xyz="0.0 -0.073535 0.0"/>
    <parent link="body_link"/>
    <child link="leg_center_RM"/>
  </joint>
  <link name="leg_center_RM">
    <inertial>
      <origin rpy="0.0 0.0 0.0" xyz="0.0 0.0 0.0"/>
      <mass value="0.05200"/>
      <inertia ixx="1.0" ixy="0.0" ixz="0.0" iyy="1.0" iyz="0.0" izz="1.0"/>
    </inertial>
  </link>
  <!-- coxa -->
  <joint name="coxa_joint_RM" type="revolute">
    <origin rpy="0.0 0.0 -1.5707963267948966" xyz="0.0 0.0 0.0"/>
    <parent link="leg_center_RM"/>
    <child link="coxa_RM"/>
    <axis xyz="0.0 0.0 1.0"/>
    <limit effort="6.0" lower="-3.14" upper="3.14" velocity="0.524"/>
    <dynamics damping="0.7"/>
  </joint>
  <link name="coxa_RM">
    <visual name="coxa_RM_visual">
      <origin rpy="0.0 0.0 0.0" xyz="0.0 0.0 0.0"/>
      <geometry>
        <mesh filename="coxa.stl" scale="0.001 0.001 0.001"/>
      </geometry>
      <material name="">
        <color rgba="0.7 0.7 0.7 1"/>
      </material>
    </visual>
    <collision name="coxa_RM_collision">
      <origin rpy="0.0 0.0 0.0" xyz="0.0 0.0 0.0"/>
      <geometry>
        <mesh filename="coxa.stl" scale="0.001 0.001 0.001"/>
      </geometry>
      <material name="">
        <color rgba="0.7 0.7 0.7 1"/>
      </material>
    </collision>
    <inertial>
      <origin rpy="0.0 0.0 0.0" xyz="0.0 0.0 0.0"/>
      <mass value="0.01312"/>
      <inertia ixx="1.0" ixy="0.0" ixz="0.0" iyy="1.0" iyz="0.0" izz="1.0"/>
    </inertial>
  </link>
  <!-- femur -->
  <joint name="femur_joint_RM" type="revolute">
    <origin rpy="1.5707963267948966 0.0 0.0" xyz="0.04505032 0.0 0.0"/>
    <parent link="coxa_RM"/>
    <child link="femur_RM"/>
    <axis xyz="0.0 0.0 1"/>
    <limit effort="6.0" lower="-3.14" upper="3.14" velocity="0.524"/>
    <dynamics damping="0.7"/>
  </joint>
  <link name="femur_RM">
    <visual name="femur_RM_visual">
      <origin rpy="0.0 0.0 0.0" xyz="0.0 0.0 0.0"/>
      <geometry>
        <mesh filename="R_femur.stl" scale="0.001 0.001 0.001"/>
      </geometry>
      <material name="">
        <color rgba="0.7 0.7 0.7 1"/>
      </material>
    </visual>
    <collision name="femur_RM_collision">
      <origin rpy="0.0 0.0 0" xyz="0.0 0.0 0.0"/>
      <geometry>
        <mesh filename="R_femur.stl" scale="0.001 0.001 0.001"/>
      </geometry>
      <material name="">
        <color rgba="0.7 0.7 0.7 1"/>
      </material>
    </collision>
    <inertial>
      <origin rpy="0.0 0.0 1.0" xyz="0.0 0.0 0.0"/>
      <mass value="0.08737"/>
      <inertia ixx="1.0" ixy="0.0" ixz="0.0" iyy="1.0" iyz="0.0" izz="1.0"/>
    </inertial>
  </link>
  <!-- tibia -->
  <joint name="tibia_joint_RM" type="revolute">
    <origin rpy="0.0 0.0 -1.5707963267948966" xyz="0.07703 0.0 0.0"/>
    <parent link="femur_RM"/>
    <child link="tibia_RM"/>
    <axis xyz="0.0 0.0 1"/>
    <limit effort="6.0" lower="-3.14" upper="3.14" velocity="0.524"/>
    <dynamics damping="0.7"/>
  </joint>
  <link name="tibia_RM">
    <visual name="tibia_RM_visual">
      <origin rpy="0.0 0.0 0.0" xyz="0.0 0.0 0.0"/>
      <geometry>
        <mesh filename="R_tibia.stl" scale="0.001 0.001 0.001"/>
      </geometry>
      <material name="">
        <color rgba="0.7 0.7 0.7 1"/>
      </material>
    </visual>
    <collision name="tibia_RM_collision">
      <origin rpy="0.0 0.0 0.0" xyz="0.0 0.0 0.0"/>
      <geometry>
        <mesh filename="R_tibia.stl" scale="0.001 0.001 0.001"/>
      </geometry>
      <material name="">
        <color rgba="0.7 0.7 0.7 1"/>
      </material>
    </collision>
    <inertial>
      <origin rpy="0.0 0.0 0.0" xyz="0.0 0.0 0.0"/>
      <mass value="0.09016"/>
      <inertia ixx="1.0" ixy="0.0" ixz="0.0" iyy="1.0" iyz="0.0" izz="1.0"/>
    </inertial>
  </link>
  <!-- END -->
  <joint name="end_jointRM" type="fixed">
    <origin rpy="0.0 0.0 0.0" xyz="0.12 0.0 0.0"/>
    <parent link="tibia_RM"/>
    <child link="end_RM"/>
    <axis xyz="0.0 0.0 0.0"/>
  </joint>
  <link name="end_RM">
        </link>
  <!-- leg position -->
  <joint name="leg_center_joint_RF" type="fixed">
    <origin rpy="0.0 0.0 0.0" xyz="0.093205 -0.05098 0.0"/>
    <parent link="body_link"/>
    <child link="leg_center_RF"/>
  </joint>
  <link name="leg_center_RF">
    <inertial>
      <origin rpy="0.0 0.0 0.0" xyz="0.0 0.0 0.0"/>
      <mass value="0.05200"/>
      <inertia ixx="1.0" ixy="0.0" ixz="0.0" iyy="1.0" iyz="0.0" izz="1.0"/>
    </inertial>
  </link>
  <!-- coxa -->
  <joint name="coxa_joint_RF" type="revolute">
    <origin rpy="0.0 0.0 -0.7853981633974483" xyz="0.0 0.0 0.0"/>
    <parent link="leg_center_RF"/>
    <child link="coxa_RF"/>
    <axis xyz="0.0 0.0 1.0"/>
    <limit effort="6.0" lower="-3.14" upper="3.14" velocity="0.524"/>
    <dynamics damping="0.7"/>
  </joint>
  <link name="coxa_RF">
    <visual name="coxa_RF_visual">
      <origin rpy="0.0 0.0 0.0" xyz="0.0 0.0 0.0"/>
      <geometry>
        <mesh filename="coxa.stl" scale="0.001 0.001 0.001"/>
      </geometry>
      <material name="">
        <color rgba="0.7 0.7 0.7 1"/>
      </material>
    </visual>
    <collision name="coxa_RF_collision">
      <origin rpy="0.0 0.0 0.0" xyz="0.0 0.0 0.0"/>
      <geometry>
        <mesh filename="coxa.stl" scale="0.001 0.001 0.001"/>
      </geometry>
      <material name="">
        <color rgba="0.7 0.7 0.7 1"/>
      </material>
    </collision>
    <inertial>
      <origin rpy="0.0 0.0 0.0" xyz="0.0 0.0 0.0"/>
      <mass value="0.01312"/>
      <inertia ixx="1.0" ixy="0.0" ixz="0.0" iyy="1.0" iyz="0.0" izz="1.0"/>
    </inertial>
  </link>
  <!-- femur -->
  <joint name="femur_joint_RF" type="revolute">
    <origin rpy="1.5707963267948966 0.0 0.0" xyz="0.04505032 0.0 0.0"/>
    <parent link="coxa_RF"/>
    <child link="femur_RF"/>
    <axis xyz="0.0 0.0 1"/>
    <limit effort="6.0" lower="-3.14" upper="3.14" velocity="0.524"/>
    <dynamics damping="0.7"/>
  </joint>
  <link name="femur_RF">
    <visual name="femur_RF_visual">
      <origin rpy="0.0 0.0 0.0" xyz="0.0 0.0 0.0"/>
      <geometry>
        <mesh filename="R_femur.stl" scale="0.001 0.001 0.001"/>
      </geometry>
      <material name="">
        <color rgba="0.7 0.7 0.7 1"/>
      </material>
    </visual>
    <collision name="femur_RF_collision">
      <origin rpy="0.0 0.0 0" xyz="0.0 0.0 0.0"/>
      <geometry>
        <mesh filename="R_femur.stl" scale="0.001 0.001 0.001"/>
      </geometry>
      <material name="">
        <color rgba="0.7 0.7 0.7 1"/>
      </material>
    </collision>
    <inertial>
      <origin rpy="0.0 0.0 1.0" xyz="0.0 0.0 0.0"/>
      <mass value="0.08737"/>
      <inertia ixx="1.0" ixy="0.0" ixz="0.0" iyy="1.0" iyz="0.0" izz="1.0"/>
    </inertial>
  </link>
  <!-- tibia -->
  <joint name="tibia_joint_RF" type="revolute">
    <origin rpy="0.0 0.0 -1.5707963267948966" xyz="0.07703 0.0 0.0"/>
    <parent link="femur_RF"/>
    <child link="tibia_RF"/>
    <axis xyz="0.0 0.0 1"/>
    <limit effort="6.0" lower="-3.14" upper="3.14" velocity="0.524"/>
    <dynamics damping="0.7"/>
  </joint>
  <link name="tibia_RF">
    <visual name="tibia_RF_visual">
      <origin rpy="0.0 0.0 0.0" xyz="0.0 0.0 0.0"/>
      <geometry>
        <mesh filename="R_tibia.stl" scale="0.001 0.001 0.001"/>
      </geometry>
      <material name="">
        <color rgba="0.7 0.7 0.7 1"/>
      </material>
    </visual>
    <collision name="tibia_RF_collision">
      <origin rpy="0.0 0.0 0.0" xyz="0.0 0.0 0.0"/>
      <geometry>
        <mesh filename="R_tibia.stl" scale="0.001 0.001 0.001"/>
      </geometry>
      <material name="">
        <color rgba="0.7 0.7 0.7 1"/>
      </material>
    </collision>
    <inertial>
      <origin rpy="0.0 0.0 0.0" xyz="0.0 0.0 0.0"/>
      <mass value="0.09016"/>
      <inertia ixx="1.0" ixy="0.0" ixz="0.0" iyy="1.0" iyz="0.0" izz="1.0"/>
    </inertial>
  </link>
  <!-- END -->
  <joint name="end_jointRF" type="fixed">
    <origin rpy="0.0 0.0 0.0" xyz="0.12 0.0 0.0"/>
    <parent link="tibia_RF"/>
    <child link="end_RF"/>
    <axis xyz="0.0 0.0 0.0"/>
  </joint>
  <link name="end_RF">
        </link>
  <!-- leg position -->
  <joint name="leg_center_joint_LR" type="fixed">
    <origin rpy="0.0 0.0 0.0" xyz="-0.093205 0.05098 0.0"/>
    <parent link="body_link"/>
    <child link="leg_center_LR"/>
  </joint>
  <link name="leg_center_LR">
    <inertial>
      <origin rpy="0.0 0.0 0.0" xyz="0.0 0.0 0.0"/>
      <mass value="0.05200"/>
      <inertia ixx="1.0" ixy="0.0" ixz="0.0" iyy="1.0" iyz="0.0" izz="1.0"/>
    </inertial>
  </link>
  <!-- coxa -->
  <joint name="coxa_joint_LR" type="revolute">
    <origin rpy="0.0 0.0 2.356194490192345" xyz="0.0 0.0 0.0"/>
    <parent link="leg_center_LR"/>
    <child link="coxa_LR"/>
    <axis xyz="0.0 0.0 1.0"/>
    <limit effort="6.0" lower="-3.14" upper="3.14" velocity="0.524"/>
    <dynamics damping="0.7"/>
  </joint>
  <link name="coxa_LR">
    <visual name="coxa_LR_visual">
      <origin rpy="0.0 0.0 0.0" xyz="0.0 0.0 0.0"/>
      <geometry>
        <mesh filename="coxa.stl" scale="0.001 0.001 0.001"/>
      </geometry>
      <material name="">
        <color rgba="0.7 0.7 0.7 1"/>
      </material>
    </visual>
    <collision name="coxa_LR_collision">
      <origin rpy="0.0 0.0 0.0" xyz="0.0 0.0 0.0"/>
      <geometry>
        <mesh filename="coxa.stl" scale="0.001 0.001 0.001"/>
      </geometry>
      <material name="">
        <color rgba="0.7 0.7 0.7 1"/>
      </material>
    </collision>
    <inertial>
      <origin rpy="0.0 0.0 0.0" xyz="0.0 0.0 0.0"/>
      <mass value="0.01312"/>
      <inertia ixx="1.0" ixy="0.0" ixz="0.0" iyy="1.0" iyz="0.0" izz="1.0"/>
    </inertial>
  </link>
  <!-- femur -->
  <joint name="femur_joint_LR" type="revolute">
    <origin rpy="-1.5707963267948966 0.0 0.0" xyz="0.04505032 0.0 0.0"/>
    <parent link="coxa_LR"/>
    <child link="femur_LR"/>
    <axis xyz="0.0 0.0 -1"/>
    <limit effort="6.0" lower="-3.14" upper="3.14" velocity="0.524"/>
    <dynamics damping="0.7"/>
  </joint>
  <link name="femur_LR">
    <visual name="femur_LR_visual">
      <origin rpy="0.0 0.0 0.0" xyz="0.0 0.0 0.0"/>
      <geometry>
        <mesh filename="L_femur.stl" scale="0.001 0.001 0.001"/>
      </geometry>
      <material name="">
        <color rgba="0.7 0.7 0.7 1"/>
      </material>
    </visual>
    <collision name="femur_LR_collision">
      <origin rpy="0.0 0.0 0" xyz="0.0 0.0 0.0"/>
      <geometry>
        <mesh filename="L_femur.stl" scale="0.001 0.001 0.001"/>
      </geometry>
      <material name="">
        <color rgba="0.7 0.7 0.7 1"/>
      </material>
    </collision>
    <inertial>
      <origin rpy="0.0 0.0 1.0" xyz="0.0 0.0 0.0"/>
      <mass value="0.08737"/>
      <inertia ixx="1.0" ixy="0.0" ixz="0.0" iyy="1.0" iyz="0.0" izz="1.0"/>
    </inertial>
  </link>
  <!-- tibia -->
  <joint name="tibia_joint_LR" type="revolute">
    <origin rpy="0.0 0.0 1.5707963267948966" xyz="0.07703 0.0 0.0"/>
    <parent link="femur_LR"/>
    <child link="tibia_LR"/>
    <axis xyz="0.0 0.0 -1"/>
    <limit effort="6.0" lower="-3.14" upper="3.14" velocity="0.524"/>
    <dynamics damping="0.7"/>
  </joint>
  <link name="tibia_LR">
    <visual name="tibia_LR_visual">
      <origin rpy="0.0 0.0 0.0" xyz="0.0 0.0 0.0"/>
      <geometry>
        <mesh filename="L_tibia.stl" scale="0.001 0.001 0.001"/>
      </geometry>
      <material name="">
        <color rgba="0.7 0.7 0.7 1"/>
      </material>
    </visual>
    <collision name="tibia_LR_collision">
      <origin rpy="0.0 0.0 0.0" xyz="0.0 0.0 0.0"/>
      <geometry>
        <mesh filename="L_tibia.stl" scale="0.001 0.001 0.001"/>
      </geometry>
      <material name="">
        <color rgba="0.7 0.7 0.7 1"/>
      </material>
    </collision>
    <inertial>
      <origin rpy="0.0 0.0 0.0" xyz="0.0 0.0 0.0"/>
      <mass value="0.09016"/>
      <inertia ixx="1.0" ixy="0.0" ixz="0.0" iyy="1.0" iyz="0.0" izz="1.0"/>
    </inertial>
  </link>
  <!-- END -->
  <joint name="end_jointLR" type="fixed">
    <origin rpy="0.0 0.0 0.0" xyz="0.12 0.0 0.0"/>
    <parent link="tibia_LR"/>
    <child link="end_LR"/>
    <axis xyz="0.0 0.0 0.0"/>
  </joint>
  <link name="end_LR">
        </link>
  <!-- leg position -->
  <joint name="leg_center_joint_LM" type="fixed">
    <origin rpy="0.0 0.0 0.0" xyz="0.0 0.07353 0.0"/>
    <parent link="body_link"/>
    <child link="leg_center_LM"/>
  </joint>
  <link name="leg_center_LM">
    <inertial>
      <origin rpy="0.0 0.0 0.0" xyz="0.0 0.0 0.0"/>
      <mass value="0.05200"/>
      <inertia ixx="1.0" ixy="0.0" ixz="0.0" iyy="1.0" iyz="0.0" izz="1.0"/>
    </inertial>
  </link>
  <!-- coxa -->
  <joint name="coxa_joint_LM" type="revolute">
    <origin rpy="0.0 0.0 1.5707963267948966" xyz="0.0 0.0 0.0"/>
    <parent link="leg_center_LM"/>
    <child link="coxa_LM"/>
    <axis xyz="0.0 0.0 1.0"/>
    <limit effort="6.0" lower="-3.14" upper="3.14" velocity="0.524"/>
    <dynamics damping="0.7"/>
  </joint>
  <link name="coxa_LM">
    <visual name="coxa_LM_visual">
      <origin rpy="0.0 0.0 0.0" xyz="0.0 0.0 0.0"/>
      <geometry>
        <mesh filename="coxa.stl" scale="0.001 0.001 0.001"/>
      </geometry>
      <material name="">
        <color rgba="0.7 0.7 0.7 1"/>
      </material>
    </visual>
    <collision name="coxa_LM_collision">
      <origin rpy="0.0 0.0 0.0" xyz="0.0 0.0 0.0"/>
      <geometry>
        <mesh filename="coxa.stl" scale="0.001 0.001 0.001"/>
      </geometry>
      <material name="">
        <color rgba="0.7 0.7 0.7 1"/>
      </material>
    </collision>
    <inertial>
      <origin rpy="0.0 0.0 0.0" xyz="0.0 0.0 0.0"/>
      <mass value="0.01312"/>
      <inertia ixx="1.0" ixy="0.0" ixz="0.0" iyy="1.0" iyz="0.0" izz="1.0"/>
    </inertial>
  </link>
  <!-- femur -->
  <joint name="femur_joint_LM" type="revolute">
    <origin rpy="-1.5707963267948966 0.0 0.0" xyz="0.04505032 0.0 0.0"/>
    <parent link="coxa_LM"/>
    <child link="femur_LM"/>
    <axis xyz="0.0 0.0 -1"/>
    <limit effort="6.0" lower="-3.14" upper="3.14" velocity="0.524"/>
    <dynamics damping="0.7"/>
  </joint>
  <link name="femur_LM">
    <visual name="femur_LM_visual">
      <origin rpy="0.0 0.0 0.0" xyz="0.0 0.0 0.0"/>
      <geometry>
        <mesh filename="L_femur.stl" scale="0.001 0.001 0.001"/>
      </geometry>
      <material name="">
        <color rgba="0.7 0.7 0.7 1"/>
      </material>
    </visual>
    <collision name="femur_LM_collision">
      <origin rpy="0.0 0.0 0" xyz="0.0 0.0 0.0"/>
      <geometry>
        <mesh filename="L_femur.stl" scale="0.001 0.001 0.001"/>
      </geometry>
      <material name="">
        <color rgba="0.7 0.7 0.7 1"/>
      </material>
    </collision>
    <inertial>
      <origin rpy="0.0 0.0 1.0" xyz="0.0 0.0 0.0"/>
      <mass value="0.08737"/>
      <inertia ixx="1.0" ixy="0.0" ixz="0.0" iyy="1.0" iyz="0.0" izz="1.0"/>
    </inertial>
  </link>
  <!-- tibia -->
  <joint name="tibia_joint_LM" type="revolute">
    <origin rpy="0.0 0.0 1.5707963267948966" xyz="0.07703 0.0 0.0"/>
    <parent link="femur_LM"/>
    <child link="tibia_LM"/>
    <axis xyz="0.0 0.0 -1"/>
    <limit effort="6.0" lower="-3.14" upper="3.14" velocity="0.524"/>
    <dynamics damping="0.7"/>
  </joint>
  <link name="tibia_LM">
    <visual name="tibia_LM_visual">
      <origin rpy="0.0 0.0 0.0" xyz="0.0 0.0 0.0"/>
      <geometry>
        <mesh filename="L_tibia.stl" scale="0.001 0.001 0.001"/>
      </geometry>
      <material name="">
        <color rgba="0.7 0.7 0.7 1"/>
      </material>
    </visual>
    <collision name="tibia_LM_collision">
      <origin rpy="0.0 0.0 0.0" xyz="0.0 0.0 0.0"/>
      <geometry>
        <mesh filename="L_tibia.stl" scale="0.001 0.001 0.001"/>
      </geometry>
      <material name="">
        <color rgba="0.7 0.7 0.7 1"/>
      </material>
    </collision>
    <inertial>
      <origin rpy="0.0 0.0 0.0" xyz="0.0 0.0 0.0"/>
      <mass value="0.09016"/>
      <inertia ixx="1.0" ixy="0.0" ixz="0.0" iyy="1.0" iyz="0.0" izz="1.0"/>
    </inertial>
  </link>
  <!-- END -->
  <joint name="end_jointLM" type="fixed">
    <origin rpy="0.0 0.0 0.0" xyz="0.12 0.0 0.0"/>
    <parent link="tibia_LM"/>
    <child link="end_LM"/>
    <axis xyz="0.0 0.0 0.0"/>
  </joint>
  <link name="end_LM">
        </link>
  <!-- leg position -->
  <joint name="leg_center_joint_LF" type="fixed">
    <origin rpy="0.0 0.0 0.0" xyz="0.093205 0.05098 0.0"/>
    <parent link="body_link"/>
    <child link="leg_center_LF"/>
  </joint>
  <link name="leg_center_LF">
    <inertial>
      <origin rpy="0.0 0.0 0.0" xyz="0.0 0.0 0.0"/>
      <mass value="0.05200"/>
      <inertia ixx="1.0" ixy="0.0" ixz="0.0" iyy="1.0" iyz="0.0" izz="1.0"/>
    </inertial>
  </link>
  <!-- coxa -->
  <joint name="coxa_joint_LF" type="revolute">
    <origin rpy="0.0 0.0 0.7853981633974483" xyz="0.0 0.0 0.0"/>
    <parent link="leg_center_LF"/>
    <child link="coxa_LF"/>
    <axis xyz="0.0 0.0 1.0"/>
    <limit effort="6.0" lower="-3.14" upper="3.14" velocity="0.524"/>
    <dynamics damping="0.7"/>
  </joint>
  <link name="coxa_LF">
    <visual name="coxa_LF_visual">
      <origin rpy="0.0 0.0 0.0" xyz="0.0 0.0 0.0"/>
      <geometry>
        <mesh filename="coxa.stl" scale="0.001 0.001 0.001"/>
      </geometry>
      <material name="">
        <color rgba="0.7 0.7 0.7 1"/>
      </material>
    </visual>
    <collision name="coxa_LF_collision">
      <origin rpy="0.0 0.0 0.0" xyz="0.0 0.0 0.0"/>
      <geometry>
        <mesh filename="coxa.stl" scale="0.001 0.001 0.001"/>
      </geometry>
      <material name="">
        <color rgba="0.7 0.7 0.7 1"/>
      </material>
    </collision>
    <inertial>
      <origin rpy="0.0 0.0 0.0" xyz="0.0 0.0 0.0"/>
      <mass value="0.01312"/>
      <inertia ixx="1.0" ixy="0.0" ixz="0.0" iyy="1.0" iyz="0.0" izz="1.0"/>
    </inertial>
  </link>
  <!-- femur -->
  <joint name="femur_joint_LF" type="revolute">
    <origin rpy="-1.5707963267948966 0.0 0.0" xyz="0.04505032 0.0 0.0"/>
    <parent link="coxa_LF"/>
    <child link="femur_LF"/>
    <axis xyz="0.0 0.0 -1"/>
    <limit effort="6.0" lower="-3.14" upper="3.14" velocity="0.524"/>
    <dynamics damping="0.7"/>
  </joint>
  <link name="femur_LF">
    <visual name="femur_LF_visual">
      <origin rpy="0.0 0.0 0.0" xyz="0.0 0.0 0.0"/>
      <geometry>
        <mesh filename="L_femur.stl" scale="0.001 0.001 0.001"/>
      </geometry>
      <material name="">
        <color rgba="0.7 0.7 0.7 1"/>
      </material>
    </visual>
    <collision name="femur_LF_collision">
      <origin rpy="0.0 0.0 0" xyz="0.0 0.0 0.0"/>
      <geometry>
        <mesh filename="L_femur.stl" scale="0.001 0.001 0.001"/>
      </geometry>
      <material name="">
        <color rgba="0.7 0.7 0.7 1"/>
      </material>
    </collision>
    <inertial>
      <origin rpy="0.0 0.0 1.0" xyz="0.0 0.0 0.0"/>
      <mass value="0.08737"/>
      <inertia ixx="1.0" ixy="0.0" ixz="0.0" iyy="1.0" iyz="0.0" izz="1.0"/>
    </inertial>
  </link>
  <!-- tibia -->
  <joint name="tibia_joint_LF" type="revolute">
    <origin rpy="0.0 0.0 1.5707963267948966" xyz="0.07703 0.0 0.0"/>
    <parent link="femur_LF"/>
    <child link="tibia_LF"/>
    <axis xyz="0.0 0.0 -1"/>
    <limit effort="6.0" lower="-3.14" upper="3.14" velocity="0.524"/>
    <dynamics damping="0.7"/>
  </joint>
  <link name="tibia_LF">
    <visual name="tibia_LF_visual">
      <origin rpy="0.0 0.0 0.0" xyz="0.0 0.0 0.0"/>
      <geometry>
        <mesh filename="L_tibia.stl" scale="0.001 0.001 0.001"/>
      </geometry>
      <material name="">
        <color rgba="0.7 0.7 0.7 1"/>
      </material>
    </visual>
    <collision name="tibia_LF_collision">
      <origin rpy="0.0 0.0 0.0" xyz="0.0 0.0 0.0"/>
      <geometry>
        <mesh filename="L_tibia.stl" scale="0.001 0.001 0.001"/>
      </geometry>
      <material name="">
        <color rgba="0.7 0.7 0.7 1"/>
      </material>
    </collision>
    <inertial>
      <origin rpy="0.0 0.0 0.0" xyz="0.0 0.0 0.0"/>
      <mass value="0.09016"/>
      <inertia ixx="1.0" ixy="0.0" ixz="0.0" iyy="1.0" iyz="0.0" izz="1.0"/>
    </inertial>
  </link>
  <!-- END -->
  <joint name="end_jointLF" type="fixed">
    <origin rpy="0.0 0.0 0.0" xyz="0.12 0.0 0.0"/>
    <parent link="tibia_LF"/>
    <child link="end_LF"/>
    <axis xyz="0.0 0.0 0.0"/>
  </joint>
  <link name="end_LF">
  </link>

</robot>
